Workbook
Name Slicer_KPI_Type: #N/A
Name Slicer_KPI_Type1: #N/A

Sheet Dynamic Dashboard
A1: Metric Total & Difference Table | K1: Dynamic Metric Chart
A2: Shows the totals for a chosen metric as well as the difference with color-coding identifying which Mode was the largest | K2: A dynamic chart that can cycle through relevant metrics with a click of the selector
A3: Maximum | D3: Minimum
A5: Years | B5: Demand Response | C5: Fixed Route | D5: Total | E5: Difference
A6: 2014 | B6: =GETPIVOTDATA("Value",'Pivot Engine'!$N$25,"Year",2014,"Mode","Demand Response") -> 3.2 | C6: =GETPIVOTDATA("Value",'Pivot Engine'!$N$25,"Year",2014,"Mode","Fixed Route Bus") -> 5.3 | D6: =SUM(B6:C6) -> 8.5 | E6: =ABS(B6-C6) -> 2.1
A7: 2015 | B7: =GETPIVOTDATA("Value",'Pivot Engine'!$N$25,"Year",2015,"Mode","Demand Response") -> 4.4 | C7: =GETPIVOTDATA("Value",'Pivot Engine'!$N$25,"Year",2015,"Mode","Fixed Route Bus") -> 5.5 | D7: =SUM(B7:C7) -> 9.9 | E7: =ABS(B7-C7) -> 1.1
A8: 2016 | B8: =GETPIVOTDATA("Value",'Pivot Engine'!$N$25,"Year",2016,"Mode","Demand Response") -> 4.4 | C8: =GETPIVOTDATA("Value",'Pivot Engine'!$N$25,"Year",2016,"Mode","Fixed Route Bus") -> 7.1 | D8: =SUM(B8:C8) -> 11.5 | E8: =ABS(B8-C8) -> 2.7
A9: 2017 | B9: =GETPIVOTDATA("Value",'Pivot Engine'!$N$25,"Year",2017,"Mode","Demand Response") -> 5.4 | C9: =GETPIVOTDATA("Value",'Pivot Engine'!$N$25,"Year",2017,"Mode","Fixed Route Bus") -> 8.1 | D9: =SUM(B9:C9) -> 13.5 | E9: =ABS(B9-C9) -> 2.7
A10: 2018 | B10: =GETPIVOTDATA("Value",'Pivot Engine'!$N$25,"Year",2018,"Mode","Demand Response") -> 6.4 | C10: =GETPIVOTDATA("Value",'Pivot Engine'!$N$25,"Year",2018,"Mode","Fixed Route Bus") -> 9.1 | D10: =SUM(B10:C10) -> 15.5 | E10: =ABS(B10-C10) -> 2.7
A11: 2019 | B11: =GETPIVOTDATA("Value",'Pivot Engine'!$N$25,"Year",2019,"Mode","Demand Response") -> 7.4 | C11: =GETPIVOTDATA("Value",'Pivot Engine'!$N$25,"Year",2019,"Mode","Fixed Route Bus") -> 10.1 | D11: =SUM(B11:C11) -> 17.5 | E11: =ABS(B11-C11) -> 2.7
A12: 2020 | B12: =GETPIVOTDATA("Value",'Pivot Engine'!$N$25,"Year",2020,"Mode","Demand Response") -> 7.3 | C12: =GETPIVOTDATA("Value",'Pivot Engine'!$N$25,"Year",2020,"Mode","Fixed Route Bus") -> 6.3 | D12: =SUM(B12:C12) -> 13.6 | E12: =ABS(B12-C12) -> 1
A13: 2021 | B13: =GETPIVOTDATA("Value",'Pivot Engine'!$N$25,"Year",2021,"Mode","Demand Response") -> 7.5 | C13: =GETPIVOTDATA("Value",'Pivot Engine'!$N$25,"Year",2021,"Mode","Fixed Route Bus") -> 4.5 | D13: =SUM(B13:C13) -> 12 | E13: =ABS(B13-C13) -> 3
A14: 2022 | B14: =GETPIVOTDATA("Value",'Pivot Engine'!$N$25,"Year",2022,"Mode","Demand Response") -> 8.5 | C14: =GETPIVOTDATA("Value",'Pivot Engine'!$N$25,"Year",2022,"Mode","Fixed Route Bus") -> 5.5 | D14: =SUM(B14:C14) -> 14 | E14: =ABS(B14-C14) -> 3
A15: 2023 | B15: =GETPIVOTDATA("Value",'Pivot Engine'!$N$25,"Year",2023,"Mode","Demand Response") -> 9.5 | C15: =GETPIVOTDATA("Value",'Pivot Engine'!$N$25,"Year",2023,"Mode","Fixed Route Bus") -> 5.4 | D15: =SUM(B15:C15) -> 14.9 | E15: =ABS(B15-C15) -> 4.1
A16: 2024 | B16: =GETPIVOTDATA("Value",'Pivot Engine'!$N$25,"Year",2024,"Mode","Demand Response") -> 7.1 | C16: =GETPIVOTDATA("Value",'Pivot Engine'!$N$25,"Year",2024,"Mode","Fixed Route Bus") -> 5.2 | D16: =SUM(B16:C16) -> 12.3 | E16: =ABS(B16-C16) -> 1.9
A17: Grand Total | B17: =SUM(B6:B16) -> 71.1 | C17: =SUM(C6:C16) -> 72.1 | D17: =SUM(D6:D16) -> 143.2 | E17: =ABS(B17-C17) -> 1

Sheet madera_transit_master
A1: Year | B1: NTD_ID | C1: Agency | D1: Mode | E1: Mode_Code | F1: Service_Area_Pop | G1: Operating_Expenses | H1: Fare_Revenue | I1: VRM | J1: VRH | K1: UPT | L1: VOMS | M1: OE_per_UPT | N1: OE_per_VRM | O1: OE_per_VRH | P1: UPT_per_VRH | Q1: UPT_per_VRM | R1: Farebox_Recovery_Pct | S1: Avg_Fleet_Age | T1: Fare_Ops_Funding | U1: Federal_Ops_Funding | V1: State_Ops_Funding | W1: Local_Ops_Funding
A2: 2014 | B2: 90199 | C2: City of Madera | D2: Fixed Route Bus | E2: MB | F2: 62514 | G2: 845828 | H2: 105350 | I2: 178186 | J2: 12560 | K2: 143710 | L2: 6 | M2: 5.89 | N2: 4.7469 | O2: 67.34 | P2: =Table2[[#This Row],[UPT]]/Table2[[#This Row],[VRH]] -> 11.441879 | Q2: 0.8065 | R2: =Table2[[#This Row],[Fare_Revenue]]/Table2[[#This Row],[Operating_Expenses]] -> 0.12455251 | S2: 5.3 | T2: N/A | U2: N/A | V2: N/A | W2: N/A
A3: 2014 | B3: 90199 | C3: City of Madera | D3: Demand Response | E3: DR | F3: 62514 | G3: 793120 | H3: 43830 | I3: 182701 | J3: 11536 | K3: 36662 | L3: 7 | M3: 21.63 | N3: 4.3411 | O3: 68.75 | P3: =Table2[[#This Row],[UPT]]/Table2[[#This Row],[VRH]] -> 3.1780513 | Q3: 0.2007 | R3: =Table2[[#This Row],[Fare_Revenue]]/Table2[[#This Row],[Operating_Expenses]] -> 0.05526276 | S3: 3.2 | T3: N/A | U3: N/A | V3: N/A | W3: N/A
A4: 2015 | B4: 90199 | C4: City of Madera | D4: Fixed Route Bus | E4: MB | F4: 62514 | G4: 712624 | H4: 91262 | I4: 163507 | J4: 12575 | K4: 131493 | L4: 6 | M4: 5.42 | N4: 4.3584 | O4: 56.67 | P4: =Table2[[#This Row],[UPT]]/Table2[[#This Row],[VRH]] -> 10.4567 | Q4: 0.8042 | R4: =Table2[[#This Row],[Fare_Revenue]]/Table2[[#This Row],[Operating_Expenses]] -> 0.12806473 | S4: 5.5 | T4: 149222 | U4: 888435 | V4: 426076 | W4: 0
A5: 2015 | B5: 90199 | C5: City of Madera | D5: Demand Response | E5: DR | F5: 62514 | G5: 751109 | H5: 30432 | I5: 186796 | J5: 12020 | K5: 40505 | L5: 7 | M5: 18.54 | N5: 4.021 | O5: 62.49 | P5: =Table2[[#This Row],[UPT]]/Table2[[#This Row],[VRH]] -> 3.3698003 | Q5: 0.2168 | R5: =Table2[[#This Row],[Fare_Revenue]]/Table2[[#This Row],[Operating_Expenses]] -> 0.04051609 | S5: 4.4 | T5: 149222 | U5: 888435 | V5: 426076 | W5: 0
A6: 2016 | B6: 90199 | C6: City of Madera | D6: Fixed Route Bus | E6: MB | F6: 64208 | G6: 846817 | H6: 89244 | I6: 171428 | J6: 12560 | K6: 108391 | L6: 7 | M6: 7.81 | N6: 4.9398 | O6: 67.42 | P6: =Table2[[#This Row],[UPT]]/Table2[[#This Row],[VRH]] -> 8.6298567 | Q6: 0.6323 | R6: =Table2[[#This Row],[Fare_Revenue]]/Table2[[#This Row],[Operating_Expenses]] -> 0.10538759 | S6: 7.1 | T6: 403352 | U6: 731682 | V6: 613552 | W6: 0
A7: 2016 | B7: 90199 | C7: City of Madera | D7: Demand Response | E7: DR | F7: 64208 | G7: 901769 | H7: 27808 | I7: 175436 | J7: 13016 | K7: 39146 | L7: 9 | M7: 23.04 | N7: 5.1402 | O7: 69.28 | P7: =Table2[[#This Row],[UPT]]/Table2[[#This Row],[VRH]] -> 3.0075292 | Q7: 0.2231 | R7: =Table2[[#This Row],[Fare_Revenue]]/Table2[[#This Row],[Operating_Expenses]] -> 0.030837166 | S7: 4.4 | T7: 403352 | U7: 731682 | V7: 613552 | W7: 0
A8: 2017 | B8: 90199 | C8: City of Madera | D8: Fixed Route Bus | E8: MB | F8: 64208 | G8: 945588 | H8: 84283 | I8: 197570 | J8: 14864 | K8: 103002 | L8: 7 | M8: 9.18 | N8: 4.7861 | O8: 63.62 | P8: =Table2[[#This Row],[UPT]]/Table2[[#This Row],[VRH]] -> 6.9296286 | Q8: 0.5213 | R8: =Table2[[#This Row],[Fare_Revenue]]/Table2[[#This Row],[Operating_Expenses]] -> 0.089132899 | S8: 8.1 | T8: 398181 | U8: 809836 | V8: 665218 | W8: 0
A9: 2017 | B9: 90199 | C9: City of Madera | D9: Demand Response | E9: DR | F9: 64208 | G9: 927647 | H9: 22732 | I9: 169178 | J9: 13354 | K9: 35661 | L9: 9 | M9: 26.01 | N9: 5.4833 | O9: 69.47 | P9: =Table2[[#This Row],[UPT]]/Table2[[#This Row],[VRH]] -> 2.6704358 | Q9: 0.2108 | R9: =Table2[[#This Row],[Fare_Revenue]]/Table2[[#This Row],[Operating_Expenses]] -> 0.024505011 | S9: 5.4 | T9: 398181 | U9: 809836 | V9: 665218 | W9: 0
A10: 2018 | B10: 90199 | C10: City of Madera | D10: Fixed Route Bus | E10: MB | F10: 66225 | G10: 1067811 | H10: 97935 | I10: 204726 | J10: 15495 | K10: 111564 | L10: 8 | M10: 9.57 | N10: 5.2158 | O10: 68.91 | P10: =Table2[[#This Row],[UPT]]/Table2[[#This Row],[VRH]] -> 7.2 | Q10: 0.5449 | R10: =Table2[[#This Row],[Fare_Revenue]]/Table2[[#This Row],[Operating_Expenses]] -> 0.091715669 | S10: 9.1 | T10: 451870 | U10: 927853 | V10: 755234 | W10: 0
A11: 2018 | B11: 90199 | C11: City of Madera | D11: Demand Response | E11: DR | F11: 66225 | G11: 1067146 | H11: 21128 | I11: 149147 | J11: 11179 | K11: 32224 | L11: 9 | M11: 33.12 | N11: 7.155 | O11: 95.46 | P11: =Table2[[#This Row],[UPT]]/Table2[[#This Row],[VRH]] -> 2.8825476 | Q11: 0.2161 | R11: =Table2[[#This Row],[Fare_Revenue]]/Table2[[#This Row],[Operating_Expenses]] -> 0.019798603 | S11: 6.4 | T11: 451870 | U11: 927853 | V11: 755234 | W11: 0
A12: 2019 | B12: 90199 | C12: City of Madera | D12: Fixed Route Bus | E12: MB | F12: 66225 | G12: 1067697 | H12: 126876 | I12: 242305 | J12: 19119 | K12: 89650 | L12: 8 | M12: 11.91 | N12: 4.4064 | O12: 55.84 | P12: =Table2[[#This Row],[UPT]]/Table2[[#This Row],[VRH]] -> 4.6890528 | Q12: 0.37 | R12: =Table2[[#This Row],[Fare_Revenue]]/Table2[[#This Row],[Operating_Expenses]] -> 0.11883147 | S12: 10.1 | T12: 426337 | U12: 909581 | V12: 813957 | W12: 0
A13: 2019 | B13: 90199 | C13: City of Madera | D13: Demand Response | E13: DR | F13: 66225 | G13: 1082178 | H13: 46970 | I13: 101922 | J13: 10313 | K13: 20981 | L13: 9 | M13: 51.58 | N13: 10.6177 | O13: 104.93 | P13: =Table2[[#This Row],[UPT]]/Table2[[#This Row],[VRH]] -> 2.0344226 | Q13: 0.2059 | R13: =Table2[[#This Row],[Fare_Revenue]]/Table2[[#This Row],[Operating_Expenses]] -> 0.043403211 | S13: 7.4 | T13: 426337 | U13: 909581 | V13: 813957 | W13: 0
A14: 2020 | B14: 90199 | C14: City of Madera | D14: Fixed Route Bus | E14: MB | F14: 66225 | G14: 1327094 | H14: 81501 | I14: 241800 | J14: 17776 | K14: 82716 | L14: 16 | M14: 16.04 | N14: 5.4884 | O14: 74.66 | P14: =Table2[[#This Row],[UPT]]/Table2[[#This Row],[VRH]] -> 4.6532403 | Q14: 0.3421 | R14: =Table2[[#This Row],[Fare_Revenue]]/Table2[[#This Row],[Operating_Expenses]] -> 0.061413133 | S14: 6.3 | T14: 145468 | U14: 1094387 | V14: 1192282 | W14: 0
A15: 2020 | B15: 90199 | C15: City of Madera | D15: Demand Response | E15: DR | F15: 66225 | G15: 1105043 | H15: 38637 | I15: 72130 | J15: 8047 | K15: 12755 | L15: 8 | M15: 86.64 | N15: 15.3202 | O15: 137.32 | P15: =Table2[[#This Row],[UPT]]/Table2[[#This Row],[VRH]] -> 1.5850628 | Q15: 0.1768 | R15: =Table2[[#This Row],[Fare_Revenue]]/Table2[[#This Row],[Operating_Expenses]] -> 0.03496425 | S15: 7.3 | T15: 145468 | U15: 1094387 | V15: 1192282 | W15: 0
... A23: 2024 | B23: 90199 | C23: City of Madera | D23: Demand Response | E23: DR | F23: 66225 | G23: 1351313 | H23: 3340 | I23: 104345 | J23: 7969 | K23: 17677 | L23: 8 | M23: 76.44 | N23: 12.9504 | O23: 169.57 | P23: =Table2[[#This Row],[UPT]]/Table2[[#This Row],[VRH]] -> 2.2182206 | Q23: 0.1694 | R23: =Table2[[#This Row],[Fare_Revenue]]/Table2[[#This Row],[Operating_Expenses]] -> 0.0024716701 | S23: 7.1 | T23: 37576 | U23: 1272285 | V23: 1990782 | W23: 0
E49: =

Sheet Pivot Engine
A1: Year | B1: NTD_ID | C1: Agency | D1: Mode | E1: Mode_Code | F1: Fare_Ops_Funding | G1: Federal_Ops_Funding | H1: State_Ops_Funding | I1: Local_Ops_Funding | J1: KPI_Type | K1: Value
A2: 2014 | B2: 90199 | C2: City of Madera | D2: Fixed Route Bus | E2: MB | F2: N/A | G2: N/A | H2: N/A | I2: N/A | J2: Service_Area_Pop | K2: 62514
A3: 2014 | B3: 90199 | C3: City of Madera | D3: Fixed Route Bus | E3: MB | F3: N/A | G3: N/A | H3: N/A | I3: N/A | J3: Operating_Expenses | K3: 845828 | N3: Dynamic Chart Table
A4: 2014 | B4: 90199 | C4: City of Madera | D4: Fixed Route Bus | E4: MB | F4: N/A | G4: N/A | H4: N/A | I4: N/A | J4: Fare_Revenue | K4: 105350
A5: 2014 | B5: 90199 | C5: City of Madera | D5: Fixed Route Bus | E5: MB | F5: N/A | G5: N/A | H5: N/A | I5: N/A | J5: VRM | K5: 178186 | N5: KPI_Type | O5: Operating_Expenses
A6: 2014 | B6: 90199 | C6: City of Madera | D6: Fixed Route Bus | E6: MB | F6: N/A | G6: N/A | H6: N/A | I6: N/A | J6: VRH | K6: 12560
A7: 2014 | B7: 90199 | C7: City of Madera | D7: Fixed Route Bus | E7: MB | F7: N/A | G7: N/A | H7: N/A | I7: N/A | J7: UPT | K7: 143710 | N7: Sum of Value | O7: Column Labels
A8: 2014 | B8: 90199 | C8: City of Madera | D8: Fixed Route Bus | E8: MB | F8: N/A | G8: N/A | H8: N/A | I8: N/A | J8: VOMS | K8: 6 | N8: Row Labels | O8: Demand Response | P8: Fixed Route Bus | Q8: Grand Total
A9: 2014 | B9: 90199 | C9: City of Madera | D9: Fixed Route Bus | E9: MB | F9: N/A | G9: N/A | H9: N/A | I9: N/A | J9: OE_per_UPT | K9: 5.89 | N9: 2014 | O9: 793120 | P9: 845828 | Q9: 1638948
A10: 2014 | B10: 90199 | C10: City of Madera | D10: Fixed Route Bus | E10: MB | F10: N/A | G10: N/A | H10: N/A | I10: N/A | J10: OE_per_VRM | K10: 4.7469 | N10: 2015 | O10: 751109 | P10: 712624 | Q10: 1463733
A11: 2014 | B11: 90199 | C11: City of Madera | D11: Fixed Route Bus | E11: MB | F11: N/A | G11: N/A | H11: N/A | I11: N/A | J11: OE_per_VRH | K11: 67.34 | N11: 2016 | O11: 901769 | P11: 846817 | Q11: 1748586
A12: 2014 | B12: 90199 | C12: City of Madera | D12: Fixed Route Bus | E12: MB | F12: N/A | G12: N/A | H12: N/A | I12: N/A | J12: UPT_per_VRH | K12: 11.441879 | N12: 2017 | O12: 927647 | P12: 945588 | Q12: 1873235
A13: 2014 | B13: 90199 | C13: City of Madera | D13: Fixed Route Bus | E13: MB | F13: N/A | G13: N/A | H13: N/A | I13: N/A | J13: UPT_per_VRM | K13: 0.8065 | N13: 2018 | O13: 1067146 | P13: 1067811 | Q13: 2134957
A14: 2014 | B14: 90199 | C14: City of Madera | D14: Fixed Route Bus | E14: MB | F14: N/A | G14: N/A | H14: N/A | I14: N/A | J14: Farebox_Recovery_Pct | K14: 0.12455251 | N14: 2019 | O14: 1082178 | P14: 1067697 | Q14: 2149875
A15: 2014 | B15: 90199 | C15: City of Madera | D15: Fixed Route Bus | E15: MB | F15: N/A | G15: N/A | H15: N/A | I15: N/A | J15: Avg_Fleet_Age | K15: 5.3 | N15: 2020 | O15: 1105043 | P15: 1327094 | Q15: 2432137
A16: 2014 | B16: 90199 | C16: City of Madera | D16: Demand Response | E16: DR | F16: N/A | G16: N/A | H16: N/A | I16: N/A | J16: Service_Area_Pop | K16: 62514 | N16: 2021 | O16: 1015851 | P16: 1377788 | Q16: 2393639
A17: 2014 | B17: 90199 | C17: City of Madera | D17: Demand Response | E17: DR | F17: N/A | G17: N/A | H17: N/A | I17: N/A | J17: Operating_Expenses | K17: 793120 | N17: 2022 | O17: 1180371 | P17: 1681016 | Q17: 2861387
A18: 2014 | B18: 90199 | C18: City of Madera | D18: Demand Response | E18: DR | F18: N/A | G18: N/A | H18: N/A | I18: N/A | J18: Fare_Revenue | K18: 43830 | N18: 2023 | O18: 1197797 | P18: 1584061 | Q18: 2781858
A19: 2014 | B19: 90199 | C19: City of Madera | D19: Demand Response | E19: DR | F19: N/A | G19: N/A | H19: N/A | I19: N/A | J19: VRM | K19: 182701 | N19: 2024 | O19: 1351313 | P19: 1949330 | Q19: 3300643
A20: 2014 | B20: 90199 | C20: City of Madera | D20: Demand Response | E20: DR | F20: N/A | G20: N/A | H20: N/A | I20: N/A | J20: VRH | K20: 11536 | N20: Grand Total | O20: 11373344 | P20: 13405654 | Q20: 24778998
A21: 2014 | B21: 90199 | C21: City of Madera | D21: Demand Response | E21: DR | F21: N/A | G21: N/A | H21: N/A | I21: N/A | J21: UPT | K21: 36662
A22: 2014 | B22: 90199 | C22: City of Madera | D22: Demand Response | E22: DR | F22: N/A | G22: N/A | H22: N/A | I22: N/A | J22: VOMS | K22: 7 | N22: Total&Difference Table
A23: 2014 | B23: 90199 | C23: City of Madera | D23: Demand Response | E23: DR | F23: N/A | G23: N/A | H23: N/A | I23: N/A | J23: OE_per_UPT | K23: 21.63 | N23: KPI_Type | O23: Avg_Fleet_Age
A24: 2014 | B24: 90199 | C24: City of Madera | D24: Demand Response | E24: DR | F24: N/A | G24: N/A | H24: N/A | I24: N/A | J24: OE_per_VRM | K24: 4.3411
A25: 2014 | B25: 90199 | C25: City of Madera | D25: Demand Response | E25: DR | F25: N/A | G25: N/A | H25: N/A | I25: N/A | J25: OE_per_VRH | K25: 68.75 | N25: Sum of Value | O25: Column Labels
A26: 2014 | B26: 90199 | C26: City of Madera | D26: Demand Response | E26: DR | F26: N/A | G26: N/A | H26: N/A | I26: N/A | J26: UPT_per_VRH | K26: 3.1780513 | N26: Row Labels | O26: Demand Response | P26: Fixed Route Bus | Q26: Grand Total
A27: 2014 | B27: 90199 | C27: City of Madera | D27: Demand Response | E27: DR | F27: N/A | G27: N/A | H27: N/A | I27: N/A | J27: UPT_per_VRM | K27: 0.2007 | N27: 2014 | O27: 3.2 | P27: 5.3 | Q27: 8.5
A28: 2014 | B28: 90199 | C28: City of Madera | D28: Demand Response | E28: DR | F28: N/A | G28: N/A | H28: N/A | I28: N/A | J28: Farebox_Recovery_Pct | K28: 0.05526276 | N28: 2015 | O28: 4.4 | P28: 5.5 | Q28: 9.9
A29: 2014 | B29: 90199 | C29: City of Madera | D29: Demand Response | E29: DR | F29: N/A | G29: N/A | H29: N/A | I29: N/A | J29: Avg_Fleet_Age | K29: 3.2 | N29: 2016 | O29: 4.4 | P29: 7.1 | Q29: 11.5
A30: 2015 | B30: 90199 | C30: City of Madera | D30: Fixed Route Bus | E30: MB | F30: 149222 | G30: 888435 | H30: 426076 | I30: 0 | J30: Service_Area_Pop | K30: 62514 | N30: 2017 | O30: 5.4 | P30: 8.1 | Q30: 13.5
A31: 2015 | B31: 90199 | C31: City of Madera | D31: Fixed Route Bus | E31: MB | F31: 149222 | G31: 888435 | H31: 426076 | I31: 0 | J31: Operating_Expenses | K31: 712624 | N31: 2018 | O31: 6.4 | P31: 9.1 | Q31: 15.5
A32: 2015 | B32: 90199 | C32: City of Madera | D32: Fixed Route Bus | E32: MB | F32: 149222 | G32: 888435 | H32: 426076 | I32: 0 | J32: Fare_Revenue | K32: 91262 | N32: 2019 | O32: 7.4 | P32: 10.1 | Q32: 17.5
A33: 2015 | B33: 90199 | C33: City of Madera | D33: Fixed Route Bus | E33: MB | F33: 149222 | G33: 888435 | H33: 426076 | I33: 0 | J33: VRM | K33: 163507 | N33: 2020 | O33: 7.3 | P33: 6.3 | Q33: 13.6
A34: 2015 | B34: 90199 | C34: City of Madera | D34: Fixed Route Bus | E34: MB | F34: 149222 | G34: 888435 | H34: 426076 | I34: 0 | J34: VRH | K34: 12575 | N34: 2021 | O34: 7.5 | P34: 4.5 | Q34: 12
A35: 2015 | B35: 90199 | C35: City of Madera | D35: Fixed Route Bus | E35: MB | F35: 149222 | G35: 888435 | H35: 426076 | I35: 0 | J35: UPT | K35: 131493 | N35: 2022 | O35: 8.5 | P35: 5.5 | Q35: 14
A36: 2015 | B36: 90199 | C36: City of Madera | D36: Fixed Route Bus | E36: MB | F36: 149222 | G36: 888435 | H36: 426076 | I36: 0 | J36: VOMS | K36: 6 | N36: 2023 | O36: 9.5 | P36: 5.4 | Q36: 14.9
A37: 2015 | B37: 90199 | C37: City of Madera | D37: Fixed Route Bus | E37: MB | F37: 149222 | G37: 888435 | H37: 426076 | I37: 0 | J37: OE_per_UPT | K37: 5.42 | N37: 2024 | O37: 7.1 | P37: 5.2 | Q37: 12.3
A38: 2015 | B38: 90199 | C38: City of Madera | D38: Fixed Route Bus | E38: MB | F38: 149222 | G38: 888435 | H38: 426076 | I38: 0 | J38: OE_per_VRM | K38: 4.3584 | N38: Grand Total | O38: 71.1 | P38: 72.1 | Q38: 143.2
A39: 2015 | B39: 90199 | C39: City of Madera | D39: Fixed Route Bus | E39: MB | F39: 149222 | G39: 888435 | H39: 426076 | I39: 0 | J39: OE_per_VRH | K39: 56.67
A40: 2015 | B40: 90199 | C40: City of Madera | D40: Fixed Route Bus | E40: MB | F40: 149222 | G40: 888435 | H40: 426076 | I40: 0 | J40: UPT_per_VRH | K40: 10.4567
...
